<?xml version="1.0" encoding="utf-8"?>
<!-- This URDF was automatically created by SolidWorks to URDF Exporter! Originally created by Stephen Brawner (brawner@gmail.com) 
     Commit Version: 1.6.0-4-g7f85cfe  Build Version: 1.6.7995.38578
     For more information, please see http://wiki.ros.org/sw_urdf_exporter -->
<robot
  name="roboprinter_description">
  <link
    name="base_link">
    <inertial>
      <origin
        xyz="-3.29639758360888E-18 6.40510956545558E-18 0.0252448902560107"
        rpy="0 0 0" />
      <mass
        value="0.528972339556969" />
      <inertia
        ixx="0.000565267350159599"
        ixy="7.20477701470394E-20"
        ixz="-1.35589134863881E-21"
        iyy="0.000565267350159599"
        iyz="1.48892540258629E-20"
        izz="0.000902847820384731" />
    </inertial>
    <visual>
      <origin
        xyz="0 0 0"
        rpy="0 0 0" />
      <geometry>
        <mesh
          filename="package://roboprinter_description/meshes/base_link.STL" />
      </geometry>
      <material
        name="">
        <color
          rgba="0.752941176470588 0.752941176470588 0.752941176470588 1" />
      </material>
    </visual>
    <collision>
      <origin
        xyz="0 0 0"
        rpy="0 0 0" />
      <geometry>
        <mesh
          filename="package://roboprinter_description/meshes/base_link.STL" />
      </geometry>
    </collision>
  </link>
  <link
    name="link1">
    <inertial>
      <origin
        xyz="0.00507209935034024 -0.000300441790189516 0.0116994245938115"
        rpy="0 0 0" />
      <mass
        value="0.0780956885827604" />
      <inertia
        ixx="2.74139429221986E-05"
        ixy="-4.7581426601598E-08"
        ixz="-4.52002661664857E-10"
        iyy="2.85023356212491E-05"
        iyz="1.79574293893268E-07"
        izz="5.24080462645915E-05" />
    </inertial>
    <visual>
      <origin
        xyz="0 0 0"
        rpy="0 0 0" />
      <geometry>
        <mesh
          filename="package://roboprinter_description/meshes/link1.STL" />
      </geometry>
      <material
        name="">
        <color
          rgba="0.752941176470588 0.752941176470588 0.752941176470588 1" />
      </material>
    </visual>
    <collision>
      <origin
        xyz="0 0 0"
        rpy="0 0 0" />
      <geometry>
        <mesh
          filename="package://roboprinter_description/meshes/link1.STL" />
      </geometry>
    </collision>
  </link>
  <joint
    name="joint1"
    type="continuous">
    <origin
      xyz="0 0 0.0535"
      rpy="0 0 0" />
    <parent
      link="base_link" />
    <child
      link="link1" />
    <axis
      xyz="0 0 1" />
    <limit
      lower="-1.5708"
      upper="1.5708"
      effort="0"
      velocity="0" />
  </joint>
  <link
    name="link2">
    <inertial>
      <origin
        xyz="1.66586907462962E-10 -0.097358513327758 -0.000842949373771198"
        rpy="0 0 0" />
      <mass
        value="0.0710552587256191" />
      <inertia
        ixx="3.51801005497061E-05"
        ixy="1.2886766012224E-13"
        ixz="-2.28168634625685E-13"
        iyy="1.05093963528104E-05"
        iyz="-2.70651104967169E-07"
        izz="3.24559133069899E-05" />
    </inertial>
    <visual>
      <origin
        xyz="0 0 0"
        rpy="0 0 0" />
      <geometry>
        <mesh
          filename="package://roboprinter_description/meshes/link2.STL" />
      </geometry>
      <material
        name="">
        <color
          rgba="0.752941176470588 0.752941176470588 0.752941176470588 1" />
      </material>
    </visual>
    <collision>
      <origin
        xyz="0 0 0"
        rpy="0 0 0" />
      <geometry>
        <mesh
          filename="package://roboprinter_description/meshes/link2.STL" />
      </geometry>
    </collision>
  </link>
  <joint
    name="joint2"
    type="continuous">
    <origin
      xyz="0.018 0.00075 0.0185"
      rpy="-1.5708 0 0" />
    <parent
      link="link1" />
    <child
      link="link2" />
    <axis
      xyz="0 0 1" />
    <limit
      lower="-1.5708"
      upper="1.5708"
      effort="0"
      velocity="0" />
  </joint>
  <link
    name="link3">
    <inertial>
      <origin
        xyz="0.00924260865916297 -0.0685971128471527 -0.000891457472441148"
        rpy="0 0 0" />
      <mass
        value="0.063710838791278" />
      <inertia
        ixx="2.32949415106812E-05"
        ixy="4.58056298766306E-08"
        ixz="-1.47447853758939E-13"
        iyy="7.69364844206756E-06"
        iyz="3.36461385700796E-07"
        izz="2.66143887657194E-05" />
    </inertial>
    <visual>
      <origin
        xyz="0 0 0"
        rpy="0 0 0" />
      <geometry>
        <mesh
          filename="package://roboprinter_description/meshes/link3.STL" />
      </geometry>
      <material
        name="">
        <color
          rgba="0.752941176470588 0.752941176470588 0.752941176470588 1" />
      </material>
    </visual>
    <collision>
      <origin
        xyz="0 0 0"
        rpy="0 0 0" />
      <geometry>
        <mesh
          filename="package://roboprinter_description/meshes/link3.STL" />
      </geometry>
    </collision>
  </link>
  <joint
    name="joint3"
    type="continuous">
    <origin
      xyz="0 -0.12025 0.000125"
      rpy="0 0 0" />
    <parent
      link="link2" />
    <child
      link="link3" />
    <axis
      xyz="0 0 1" />
    <limit
      lower="-1.5708"
      upper="1.5708"
      effort="0"
      velocity="0" />
  </joint>
  <link
    name="link4">
    <inertial>
      <origin
        xyz="1.11022302462516E-16 -0.00240405152854635 0.0256295741808176"
        rpy="0 0 0" />
      <mass
        value="0.0574652082257363" />
      <inertia
        ixx="1.35787495117706E-05"
        ixy="2.05795510120988E-21"
        ixz="-1.44833338790548E-21"
        iyy="1.07767966077502E-05"
        iyz="1.55705095507992E-07"
        izz="9.2117235835035E-06" />
    </inertial>
    <visual>
      <origin
        xyz="0 0 0"
        rpy="0 0 0" />
      <geometry>
        <mesh
          filename="package://roboprinter_description/meshes/link4.STL" />
      </geometry>
      <material
        name="">
        <color
          rgba="0.752941176470588 0.752941176470588 0.752941176470588 1" />
      </material>
    </visual>
    <collision>
      <origin
        xyz="0 0 0"
        rpy="0 0 0" />
      <geometry>
        <mesh
          filename="package://roboprinter_description/meshes/link4.STL" />
      </geometry>
    </collision>
  </link>
  <joint
    name="joint4"
    type="continuous">
    <origin
      xyz="0.0375 -0.085 -0.000625"
      rpy="-1.5708 0 -1.5708" />
    <parent
      link="link3" />
    <child
      link="link4" />
    <axis
      xyz="0 0 1" />
    <limit
      lower="-1.5708"
      upper="1.5708"
      effort="0"
      velocity="0" />
  </joint>
  <link
    name="link5">
    <inertial>
      <origin
        xyz="0.000135673462176855 -0.0516824795785821 -0.000269379470015593"
        rpy="0 0 0" />
      <mass
        value="0.0613661556558953" />
      <inertia
        ixx="1.15764077279977E-05"
        ixy="4.58049748437246E-08"
        ixz="8.94951420120586E-21"
        iyy="9.79155800814954E-06"
        iyz="2.0759913512661E-07"
        izz="1.70267491333011E-05" />
    </inertial>
    <visual>
      <origin
        xyz="0 0 0"
        rpy="0 0 0" />
      <geometry>
        <mesh
          filename="package://roboprinter_description/meshes/link5.STL" />
      </geometry>
      <material
        name="">
        <color
          rgba="0.752941176470588 0.752941176470588 0.752941176470588 1" />
      </material>
    </visual>
    <collision>
      <origin
        xyz="0 0 0"
        rpy="0 0 0" />
      <geometry>
        <mesh
          filename="package://roboprinter_description/meshes/link5.STL" />
      </geometry>
    </collision>
  </link>
  <joint
    name="joint5"
    type="continuous">
    <origin
      xyz="0 -0.004 0.03725"
      rpy="-1.5708 0 -3.1416" />
    <parent
      link="link4" />
    <child
      link="link5" />
    <axis
      xyz="0 0 1" />
    <limit
      lower="-1.5708"
      upper="1.5708"
      effort="0"
      velocity="0" />
  </joint>
  <link
    name="link6">
    <inertial>
      <origin
        xyz="0.0143595422392718 -0.000612672832744842 0.0047999736628663"
        rpy="0 0 0" />
      <mass
        value="0.00271172671570455" />
      <inertia
        ixx="1.71332219642541E-07"
        ixy="9.37180381460327E-09"
        ixz="-5.42937694243123E-08"
        iyy="2.89686808729506E-07"
        iyz="9.57903170943266E-09"
        izz="3.18465730413809E-07" />
    </inertial>
    <visual>
      <origin
        xyz="0 0 0"
        rpy="0 0 0" />
      <geometry>
        <mesh
          filename="package://roboprinter_description/meshes/link6.STL" />
      </geometry>
      <material
        name="">
        <color
          rgba="0.792156862745098 0.819607843137255 0.933333333333333 1" />
      </material>
    </visual>
    <collision>
      <origin
        xyz="0 0 0"
        rpy="0 0 0" />
      <geometry>
        <mesh
          filename="package://roboprinter_description/meshes/link6.STL" />
      </geometry>
    </collision>
  </link>
  <joint
    name="joint6"
    type="continuous">
    <origin
      xyz="0.01 -0.084649 0"
      rpy="-1.5708 0 3.1416" />
    <parent
      link="link5" />
    <child
      link="link6" />
    <axis
      xyz="0 0 1" />
    <limit
      lower="-1.5708"
      upper="1.5708"
      effort="0"
      velocity="0" />
  </joint>
  <link
    name="end_effector">
    <inertial>
      <origin
        xyz="4.70253176676483E-12 -9.25969745324551E-10 -0.0742532271411501"
        rpy="0 0 0" />
      <mass
        value="0.0118315685530414" />
      <inertia
        ixx="1.22920468793244E-05"
        ixy="5.63748568852987E-14"
        ixz="-1.11700708800501E-15"
        iyy="1.23044609312459E-05"
        iyz="1.21000481097898E-13"
        izz="1.94618918342423E-07" />
    </inertial>
    <visual>
      <origin
        xyz="0 0 0"
        rpy="0 0 0" />
      <geometry>
        <mesh
          filename="package://roboprinter_description/meshes/end_effector.STL" />
      </geometry>
      <material
        name="">
        <color
          rgba="0.792156862745098 0.819607843137255 0.933333333333333 1" />
      </material>
    </visual>
    <collision>
      <origin
        xyz="0 0 0"
        rpy="0 0 0" />
      <geometry>
        <mesh
          filename="package://roboprinter_description/meshes/end_effector.STL" />
      </geometry>
    </collision>
  </link>
  <joint
    name="effector_joint"
    type="fixed">
    <origin
      xyz="-0.04 0 0.0105"
      rpy="-1.5708 0 1.5708" />
    <parent
      link="link6" />
    <child
      link="end_effector" />
    <axis
      xyz="0 0 0" />
  </joint>
</robot>